<?xml version="1.0" encoding="utf-8"?>
<!-- This URDF was automatically created by SolidWorks to URDF Exporter! Originally created by Stephen Brawner (brawner@gmail.com) 
     Commit Version: 1.6.0-4-g7f85cfe  Build Version: 1.6.7995.38578
     For more information, please see http://wiki.ros.org/sw_urdf_exporter -->
<robot name="oven">
  <link name="base_link">
    <inertial>
      <origin xyz="-0.045076 -0.04728 0.27093" rpy="0 0 0" />
      <mass value="10" />
      <inertia ixx="12.428" ixy="0.808" ixz="0.17185" iyy="7.6088" iyz="0.40258" izz="10.668" />
    </inertial>
    <visual>
      <origin xyz="0 0 0" rpy="0 0 0" />
      <geometry>
        <mesh filename="meshes/base_link.stl" />
      </geometry>
      <material name="">
        <color rgba="0.79216 0.81961 0.93333 1" />
      </material>
    </visual>
    <collision>
      <origin xyz="0 0 0" rpy="0 0 0" />
      <geometry>
        <mesh filename="meshes/base_link.stl" />
      </geometry>
    </collision>
  </link>
  <joint name="body_door_joint" type="revolute">
    <origin xyz="0.2425 0.35 0.43" rpy="0 0 0" />
    <parent link="base_link" />
    <child link="door_link" />
    <axis xyz="0 0 1" />
    <limit lower="0" upper="3.14" effort="100" velocity="10" />
  </joint>
  <link name="door_link">
    <inertial>
      <origin xyz="0 -0.30722 -0.14419" rpy="0 0 0" />
      <mass value="3" />
      <inertia ixx="0.53402" ixy="0" ixz="0" iyy="0.26539" iyz="-0.0023249" izz="0.27009" />
    </inertial>
    <visual>
      <origin xyz="-0.2425 -0.35 -0.43" rpy="0 0 0" />
      <geometry>
        <mesh filename="meshes/door_link.stl" />
      </geometry>
      <material name="">
        <color rgba="0.79216 0.81961 0.93333 1" />
      </material>
    </visual>
    <collision>
      <origin xyz="-0.2425 -0.35 -0.43" rpy="0 0 0" />
      <geometry>
        <mesh filename="meshes/door_link.stl" />
      </geometry>
    </collision>
  </link>
  <joint name="door_handle_joint" type="revolute">
    <origin xyz="-0.015 -0.53 -0.145" rpy="0 0 0" />
    <parent link="door_link" />
    <child link="handle_link" />
    <axis xyz="-1 0 0" />
    <limit lower="-1.57" upper="1.57" effort="100" velocity="10" />
  </joint>
  <link name="handle_link">
    <inertial>
      <origin xyz="0.063113 0.047728 0" rpy="0 0 0" />
      <mass value="1" />
      <inertia ixx="0.0047297" ixy="-0.00075176" ixz="0" iyy="0.00093388" iyz="0" izz="0.0051703" />
    </inertial>
    <visual>
      <origin xyz="-0.241 0.18 -0.285" rpy="0 0 0" />
      <geometry>
        <mesh filename="meshes/handle_link.stl" />
      </geometry>
      <material name="">
        <color rgba="0.79216 0.81961 0.93333 1" />
      </material>
    </visual>
    <collision>
      <origin xyz="-0.241 0.18 -0.285" rpy="0 0 0" />
      <geometry>
        <mesh filename="meshes/handle_link.stl" />
      </geometry>
    </collision>
  </link>
</robot>